package chap11;

public class UsingExceptions {
    public static void main(String[] args) {
        try {
            throwException();
        } catch (Exception exception) { // exceção lançada por throwException
            System.err.println("Exception handled in main");
        }

        doesNotThrowException();
    }

    // demonstra try...catch...finally
    public static void throwException() throws Exception {
        try {   // lança uma exceção e imediatamente a captura
            System.out.println("Method throwException");
            throw new Exception();  // gera a exceção
        } catch (Exception exception) { // captura exceção lançada em try
            System.err.println("Exception handled in method throwException");
            throw exception;    // lança novamente para processamento adicional

            // o código aqui não seria alcançado; poderia causar erros de compilação
        } finally { // executa independentemente do que ocorre em try...catch
            System.err.println("Finally executed in throwException");
        }

        // o código aqui não seria alcançado; poderia causar erros de compilação
    }

    // demonstra finally quando nenhuma exceção ocorrer
    public static void doesNotThrowException() {
        try {   // bloco try não lança uma exceção
            System.out.println("Method doesNotThrowException");
        } catch (Exception exception) { // não executa
            System.err.println(exception);
        } finally { // executa independente do que ocorre em try...catch
            System.err.println("Finally executed in doesNotThrowException");
        }

        System.out.println("End of method doesNotThrowException");
    }
}
